<?xml version="1.0"?>
<robot name="rover">
  

<link name="parent_link"/>

<link name="base_link">
<inertial>
    <origin xyz="0.0 0.0 0.0" rpy="0.0 0.0 0.0"/>
    <mass value="1.0"/>
    <inertia ixx="0.4" ixy="0.0" ixz="0.0" iyy="0.4" iyz="0.0" izz="0.2"/>
</inertial>

<visual>
    <geometry>
      <box size="0.8 0.7 0.1" />
    </geometry>
    <material name="Black">
      <color rgba="1.0 0.0 0.0 1.0"/>
    </material>
</visual>
</link>

<joint name="base_joint" type="fixed">
  <parent link="parent_link"/>
  <child link="base_link"/>
  <origin xyz="0 0 0" rpy="0 0 0"/>
</joint>


<!-- front_left_wheel -->

    <link name="wheel_front_left_link">
        <visual>
            <geometry>
                <cylinder radius="0.15" length="0.1"/>
            </geometry>
            <material name="Black">
                <color rgba="0.0 0.0 1.0 1.0"/>
            </material>
        </visual>
        <collision>
            <geometry>
                <cylinder radius="0.15" length="0.1"/>
            </geometry>
        </collision>
        <inertial>
            <mass value="1.0"/>
            <origin xyz="0.0 0.0 0.0" rpy="0.0 0.0 0.0"/>
            <inertia ixx="0.0" ixy="0.0" ixz="0.0" iyy="0.0" iyz="0.0" izz="0.0"/>
        </inertial>
    </link>

    <joint name="wheel_front_left_joint" type="continuous">
        <parent link="base_link"/>
        <child link="wheel_front_left_link"/>
        <origin xyz="-0.25 -0.4 0" rpy="1.57 0 0"/>
        <axis xyz="0 0 1"/>
    </joint>

<!-- front_right_wheel -->

    <link name="wheel_front_right_link">
    <visual>
        <geometry>
            <cylinder radius="0.15" length="0.1"/>
        </geometry>
        <material name="Black">
            <color rgba="0.0 0.0 1.0 1.0"/>
        </material>
    </visual>
    <collision>
        <geometry>
            <cylinder radius="0.15" length="0.1"/>
        </geometry>
    </collision>
    <inertial>
        <mass value="1.0"/>
        <origin xyz="0.0 0.0 0.0" rpy="0.0 0.0 0.0"/>
        <inertia ixx="0.0" ixy="0.0" ixz="0.0" iyy="0.0" iyz="0.0" izz="0.0"/>
    </inertial>
</link>

<joint name="wheel_front_right_joint" type="continuous">
    <parent link="base_link"/>
    <child link="wheel_front_right_link"/>
    <origin xyz="-0.25 0.4 0" rpy="1.57 0 0"/>
    <axis xyz="0 0 1"/>
</joint>

<!-- rear_left_wheel -->


    <link name="wheel_rear_left_link">
        <visual>
            <geometry>
                <cylinder radius="0.15" length="0.1"/>
            </geometry>
            <material name="Black">
                <color rgba="0.0 0.0 1.0 1.0"/>
            </material>
        </visual>
        <collision>
            <geometry>
                <cylinder radius="0.15" length="0.1"/>
            </geometry>
        </collision>
        <inertial>
            <mass value="1.0"/>
            <origin xyz="0.0 0.0 0.0" rpy="0.0 0.0 0.0"/>
            <inertia ixx="0.0" ixy="0.0" ixz="0.0" iyy="0.0" iyz="0.0" izz="0.0"/>
        </inertial>
    </link>

    <joint name="wheel_rear_left_joint" type="continuous">
        <parent link="base_link"/>
        <child link="wheel_rear_left_link"/>
        <origin xyz="0.25 -0.4 0" rpy="1.57 0 0"/>
        <axis xyz="0 0 1"/>
    </joint>

<!-- rear_right_wheel -->
    <link name="wheel_rear_right_link">
    <visual>
        <geometry>
            <cylinder radius="0.15" length="0.1"/>
        </geometry>
        <material name="Black">
            <color rgba="0.0 0.0 1.0 1.0"/>
        </material>
    </visual>
    <collision>
        <geometry>
            <cylinder radius="0.15" length="0.1"/>
        </geometry>
    </collision>
    <inertial>
        <mass value="1.0"/>
        <origin xyz="0.0 0.0 0.0" rpy="0.0 0.0 0.0"/>
        <inertia ixx="0.0" ixy="0.0" ixz="0.0" iyy="0.0" iyz="0.0" izz="0.0"/>
    </inertial>
</link>

<joint name="wheel_rear_right_joint" type="continuous">
    <parent link="base_link"/>
    <child link="wheel_rear_right_link"/>
    <origin xyz="0.25 0.4 0" rpy="1.57 0 0"/>
    <axis xyz="0 0 1"/>
</joint>

<gazebo>
  <plugin name="differential_drive_controller" filename="libgazebo_ros_diff_drive.so">

    <!-- Plugin update rate in Hz -->
    <updateRate>10</updateRate>

    <!-- Name of left joint, defaults to `left_joint` -->
    <leftJoint>wheel_rear_left_joint</leftJoint>

    <!-- Name of right joint, defaults to `right_joint` -->
    <rightJoint>wheel_rear_right_joint</rightJoint>

    <!-- The distance from the center of one wheel to the other, in meters, defaults to 0.34 m -->
    <wheelSeparation>0.8</wheelSeparation>

    <!-- Diameter of the wheels, in meters, defaults to 0.15 m -->
    <wheelDiameter>0.3</wheelDiameter>

    <!-- Wheel acceleration, in rad/s^2, defaults to 0.0 rad/s^2 -->
    <wheelAcceleration>1.0</wheelAcceleration>

    <!-- Maximum torque which the wheels can produce, in Nm, defaults to 5 Nm -->
    <wheelTorque>20</wheelTorque>

    <!-- Topic to receive geometry_msgs/Twist message commands, defaults to `cmd_vel` -->
    <commandTopic>cmd_vel</commandTopic>

    <!-- Topic to publish nav_msgs/Odometry messages, defaults to `odom` -->
    <odometryTopic>odom</odometryTopic>

    <!-- Odometry frame, defaults to `odom` -->
    <odometryFrame>odom</odometryFrame>

    <!-- Robot frame to calculate odometry from, defaults to `base_footprint` -->
    <robotBaseFrame>base_footprint</robotBaseFrame>

    <!-- Odometry source, 0 for ENCODER, 1 for WORLD, defaults to WORLD -->
    <odometrySource>1</odometrySource>

    <!-- Set to true to publish transforms for the wheel links, defaults to false -->
    <publishWheelTF>true</publishWheelTF>

    <!-- Set to true to publish transforms for the odometry, defaults to true -->
    <publishOdom>true</publishOdom>
    <publishOdomTF>true</publishOdomTF>

    <!-- Set to true to publish sensor_msgs/JointState on /joint_states for the wheel joints, defaults to false -->
    <publishWheelJointState>true</publishWheelJointState>

    <!-- Set to true to swap right and left wheels, defaults to true -->
    <legacyMode>false</legacyMode>
  </plugin>
</gazebo>

<gazebo>
  <plugin name="differential_drive_controller" filename="libgazebo_ros_diff_drive.so">

    <!-- Plugin update rate in Hz -->
    <updateRate>10</updateRate>

    <!-- Name of left joint, defaults to `left_joint` -->
    <leftJoint>wheel_rear_left_joint</leftJoint>

    <!-- Name of right joint, defaults to `right_joint` -->
    <rightJoint>wheel_rear_right_joint</rightJoint>

    <!-- The distance from the center of one wheel to the other, in meters, defaults to 0.34 m -->
    <wheelSeparation>0.8</wheelSeparation>

    <!-- Diameter of the wheels, in meters, defaults to 0.15 m -->
    <wheelDiameter>0.3</wheelDiameter>

    <!-- Wheel acceleration, in rad/s^2, defaults to 0.0 rad/s^2 -->
    <wheelAcceleration>1.0</wheelAcceleration>

    <!-- Maximum torque which the wheels can produce, in Nm, defaults to 5 Nm -->
    <wheelTorque>20</wheelTorque>

    <!-- Topic to receive geometry_msgs/Twist message commands, defaults to `cmd_vel` -->
    <commandTopic>cmd_vel</commandTopic>

    <!-- Topic to publish nav_msgs/Odometry messages, defaults to `odom` -->
    <odometryTopic>odom</odometryTopic>

    <!-- Odometry frame, defaults to `odom` -->
    <odometryFrame>odom</odometryFrame>

    <!-- Robot frame to calculate odometry from, defaults to `base_footprint` -->
    <robotBaseFrame>base_footprint</robotBaseFrame>

    <!-- Odometry source, 0 for ENCODER, 1 for WORLD, defaults to WORLD -->
    <odometrySource>1</odometrySource>

    <!-- Set to true to publish transforms for the wheel links, defaults to false -->
    <publishWheelTF>true</publishWheelTF>

    <!-- Set to true to publish transforms for the odometry, defaults to true -->
    <publishOdom>true</publishOdom>
    <publishOdomTF>true</publishOdomTF>

    <!-- Set to true to publish sensor_msgs/JointState on /joint_states for the wheel joints, defaults to false -->
    <publishWheelJointState>true</publishWheelJointState>

    <!-- Set to true to swap right and left wheels, defaults to true -->
    <legacyMode>false</legacyMode>
  </plugin>
</gazebo>
  




</robot>